
Loading datasets, it could take some time....
Training starts













 93%|██████████████████████████████████████████████████████████████████████████████████████████████████████████████████████████████         | 28/30 [00:27<00:01,  1.01it/s]
T_train: 29.408570528030396s
T_test: 0.07067036628723145s
100%|███████████████████████████████████████████████████████████████████████████████████████████████████████████████████████████████████████| 30/30 [00:29<00:00,  1.02it/s]
Traceback (most recent call last):
  File "/home/francesco.pugnaloni/TableEmbeddingsWithGNNs/GNNTE.py", line 313, in <module>
    run_GNNTE_experiment('GNNTE', dir, lr, batch_size, num_epochs, out_channels, n_layers, dropout)
  File "/home/francesco.pugnaloni/TableEmbeddingsWithGNNs/GNNTE.py", line 297, in run_GNNTE_experiment
    train_test_pipeline(triples_path, graphs_path, checkpoint, out_channels, n_layers,
  File "/home/francesco.pugnaloni/TableEmbeddingsWithGNNs/GNNTE.py", line 126, in train_test_pipeline
    wandb.log({"T_train":t_train, "T_test":t_test, "MSE":mse}, plot=False)
  File "/home/francesco.pugnaloni/anaconda3/envs/HPIPyG/lib/python3.11/site-packages/wandb/sdk/wandb_run.py", line 391, in wrapper
    return func(self, *args, **kwargs)
           ^^^^^^^^^^^^^^^^^^^^^^^^^^^
  File "/home/francesco.pugnaloni/anaconda3/envs/HPIPyG/lib/python3.11/site-packages/wandb/sdk/wandb_run.py", line 342, in wrapper_fn
    return func(self, *args, **kwargs)
           ^^^^^^^^^^^^^^^^^^^^^^^^^^^
  File "/home/francesco.pugnaloni/anaconda3/envs/HPIPyG/lib/python3.11/site-packages/wandb/sdk/wandb_run.py", line 332, in wrapper
    return func(self, *args, **kwargs)
           ^^^^^^^^^^^^^^^^^^^^^^^^^^^
TypeError: Run.log() got an unexpected keyword argument 'plot'